<?xml version="1.0"?>
<robot name="cylindrical_robot">

  <!-- Base Link -->
  <link name="base_link">
    <visual>
      <geometry>
        <box size="0.2 0.2 0.05" />
      </geometry>
      <origin xyz="0 0 0" rpy="0 0 0" />
    </visual>
  </link>

  <!-- Joint 1 (Base to Link 1) -->
  <joint name="joint_1" type="revolute">
    <parent link="base_link" />
    <child link="link_1" />
    <origin xyz="0 0 0.025" rpy="0 0 0" />
    <axis xyz="0 0 1" />
    <limit lower="-3.14" upper="3.14" effort="10" velocity="1" />
  </joint>

  <!-- Link 1 -->
  <link name="link_1">
    <visual>
      <geometry>
        <cylinder radius="0.1" length="1" />
      </geometry>
      <origin xyz="0 0 0.5" rpy="0 0 0" />
    </visual>
    <collision>
      <geometry>
        <cylinder radius="0.1" length="1" />
      </geometry>
      <origin xyz="0 0 0.5" rpy="0 0 0" />
    </collision>
  </link>

  <!-- Joint 2 (Link 1 to Link 2) -->
  <joint name="joint_2" type="revolute">
    <parent link="link_1" />
    <child link="link_2" />
    <origin xyz="0 0 1" rpy="0 0 0" />
    <axis xyz="0 1 0" />
    <limit lower="-3.14" upper="3.14" effort="10" velocity="1" />
  </joint>

  <!-- Link 2 -->
  <link name="link_2">
    <visual>
      <geometry>
        <cylinder radius="0.1" length="1" />
      </geometry>
      <origin xyz="0 0 0.5" rpy="0 0 0" />
    </visual>
    <collision>
      <geometry>
        <cylinder radius="0.1" length="1" />
      </geometry>
      <origin xyz="0 0 0.5" rpy="0 0 0" />
    </collision>
  </link>

  <!-- Joint 3 (Link 2 to Link 3) -->
  <joint name="joint_3" type="revolute">
    <parent link="link_2" />
    <child link="link_3" />
    <origin xyz="0 0 1" rpy="0 0 0" />
    <axis xyz="1 0 0" />
    <limit lower="-3.14" upper="3.14" effort="10" velocity="1" />
  </joint>

  <!-- Link 3 -->
  <link name="link_3">
    <visual>
      <geometry>
        <cylinder radius="0.1" length="1" />
      </geometry>
      <origin xyz="0 0 0.5" rpy="0 0 0" />
    </visual>
    <collision>
      <geometry>
        <cylinder radius="0.1" length="1" />
      </geometry>
      <origin xyz="0 0 0.5" rpy="0 0 0" />
    </collision>
  </link>

  <!-- Joint 4 (Link 3 to End Effector) -->
  <joint name="joint_4" type="fixed">
    <parent link="link_3" />
    <child link="end_effector" />
    <origin xyz="0 0 0.5" rpy="0 0 0" />
  </joint>

  <!-- End Effector Link -->
  <link name="end_effector">
    <visual>
      <geometry>
        <sphere radius="0.05" />
      </geometry>
      <origin xyz="0 0 0.5" rpy="0 0 0" />
      <material name="blue">
        <color rgba="0 0 1 1" /> <!-- RGBA for blue -->
      </material>   
    </visual>
  </link>


</robot>
